Workbook

Sheet Summary
A1: PRICE QUOTES MASTER SUMMARY
A2: Fanvill Hardware Cabalwan | Tacloban
A4: Quote # | B4: Date | C4: Rep | D4: Items Count | E4: Total Capital | F4: Total Selling Price | G4: Sheet Link
A5: 01 | B5: 9/28/2026 | C5: AIZA | D5: 56 | E5: ='Quote 01'!E64 -> 0 | F5: ='Quote 01'!G64 -> 398960 | G5: Quote 01
A6: 02 | B6: 9/28/2026 | C6: AIZA | D6: 27 | E6: ='Quote 02'!E35 -> 0 | F6: ='Quote 02'!G35 -> 17590 | G6: Quote 02
A7: 03 | B7: 9/28/2026 | C7: AIZA | D7: 9 | E7: ='Quote 03'!E17 -> 0 | F7: ='Quote 03'!G17 -> 6570 | G7: Quote 03
A8: 04 | B8: 9/28/2026 | C8: AIZA | D8: 11 | E8: ='Quote 04'!E19 -> 0 | F8: ='Quote 04'!G19 -> 12375 | G8: Quote 04
A9: 05 | B9: 9/28/2026 | C9: AIZA | D9: 11 | E9: ='Quote 05'!E19 -> 0 | F9: ='Quote 05'!G19 -> 2590 | G9: Quote 05
A10: 06 | B10: 9/30/2026 | C10: AIZA | D10: 15 | E10: ='Quote 06'!E23 -> 0 | F10: ='Quote 06'!G23 -> 16310 | G10: Quote 06
A11: 07 | B11: 9/30/2026 | C11: AIZA | D11: 25 | E11: ='Quote 07'!E33 -> 0 | F11: ='Quote 07'!G33 -> 23946 | G11: Quote 07
A12: 08 | B12: 10/1/2026 | C12: AIZA | D12: 4 | E12: ='Quote 08'!E12 -> 0 | F12: ='Quote 08'!G12 -> 5690 | G12: Quote 08
A13: 09 | B13: 10/1/2026 | C13: AIZA | D13: 25 | E13: ='Quote 09'!E33 -> 0 | F13: ='Quote 09'!G33 -> 35500 | G13: Quote 09
A14: 10 | B14: 10/2/2026 | C14: AIZA | D14: 16 | E14: ='Quote 10'!E24 -> 0 | F14: ='Quote 10'!G24 -> 5229 | G14: Quote 10
A15: 11 | B15: 10/2/2026 | C15: AIZA | D15: 19 | E15: ='Quote 11'!E27 -> 0 | F15: ='Quote 11'!G27 -> 9530 | G15: Quote 11
A16: 12 | B16: 9/28/2026 | C16: AIZA | D16: 8 | E16: ='Quote 12'!E16 -> 0 | F16: ='Quote 12'!G16 -> 8485 | G16: Quote 12
A17: 13 | B17: 9/29/2026 | C17: AIZA | D17: 12 | E17: ='Quote 13'!E20 -> 0 | F17: ='Quote 13'!G20 -> 8701.9 | G17: Quote 13
A18: 14 | B18: 9/29/2026 | C18: AIZA | D18: 5 | E18: ='Quote 14'!E13 -> 0 | F18: ='Quote 14'!G13 -> 17985 | G18: Quote 14
A19: 15 | B19: 10/1/2026 | C19: AIZA | D19: 17 | E19: ='Quote 15'!E25 -> 0 | F19: ='Quote 15'!G25 -> 10247 | G19: Quote 15
A20: 16 | B20: 10/2/2026 | C20: AIZA | D20: 6 | E20: ='Quote 16'!E14 -> 0 | F20: ='Quote 16'!G14 -> 3920 | G20: Quote 16
A21: 17 | B21: 10/2/2026 | C21: AIZA | D21: 22 | E21: ='Quote 17'!E30 -> 0 | F21: ='Quote 17'!G30 -> 8542.5 | G21: Quote 17
A22: 18 | B22: 10/6/2026 | C22: AIZA | D22: 16 | E22: ='Quote 18'!E24 -> 0 | F22: ='Quote 18'!G24 -> 16106 | G22: Quote 18
A23: 19 | B23: 10/12/2026 | C23: AIZA | D23: 12 | E23: ='Quote 19'!E20 -> 0 | F23: ='Quote 19'!G20 -> 16760 | G23: Quote 19
A24: 20 | B24: 10/7/2026 | C24: AIZA | D24: 1 | E24: ='Quote 20'!E9 -> 0 | F24: ='Quote 20'!G9 -> 33902.5 | G24: Quote 20
A25: 21 | B25: 10/7/2026 | C25: AIZA | D25: 3 | E25: ='Quote 21'!E11 -> 0 | F25: ='Quote 21'!G11 -> 44325 | G25: Quote 21
A26: 22 | B26: 10/5/2026 | C26: AIZA | D26: 21 | E26: ='Quote 22'!E29 -> 0 | F26: ='Quote 22'!G29 -> 14450 | G26: Quote 22
A27: 23 | B27: 10/5/2026 | C27: AIZA | D27: 14 | E27: ='Quote 23'!E22 -> 0 | F27: ='Quote 23'!G22 -> 20640 | G27: Quote 23
A28: 24 | B28: 10/2/2026 | C28: AIZA | D28: 9 | E28: ='Quote 24'!E17 -> 0 | F28: ='Quote 24'!G17 -> 6420 | G28: Quote 24
A29: 25 | B29: 10/7/2026 | C29: AIZA | D29: 1 | E29: ='Quote 25'!E9 -> 0 | F29: ='Quote 25'!G9 -> 3430 | G29: Quote 25
A30: 26 | B30: 10/5/2026 | C30: AIZA | D30: 28 | E30: ='Quote 26'!E36 -> 0 | F30: ='Quote 26'!G36 -> 26275 | G30: Quote 26
A31: 27 | B31: 10/12/2026 | C31: AIZA | D31: 10 | E31: ='Quote 27'!E18 -> 0 | F31: ='Quote 27'!G18 -> 12575 | G31: Quote 27
A32: 28 | B32: 10/12/2026 | C32: AIZA | D32: 5 | E32: ='Quote 28'!E13 -> 0 | F32: ='Quote 28'!G13 -> 5435 | G32: Quote 28
A33: 29 | B33: 10/12/2026 | C33: AIZA | D33: 5 | E33: ='Quote 29'!E13 -> 0 | F33: ='Quote 29'!G13 -> 6271.5 | G33: Quote 29
A34: 30 | B34: 10/12/2026 | C34: AIZA | D34: 31 | E34: ='Quote 30'!E39 -> 0 | F34: ='Quote 30'!G39 -> 18845 | G34: Quote 30
A35: 31 | B35: 10/15/2026 | C35: AIZA | D35: 16 | E35: ='Quote 31'!E24 -> 0 | F35: ='Quote 31'!G24 -> 27295 | G35: Quote 31
A36: 32 | B36: 10/15/2026 | C36: AIZA | D36: 14 | E36: ='Quote 32'!E22 -> 0 | F36: ='Quote 32'!G22 -> 17240 | G36: Quote 32
A37: 33 | B37: 10/16/2026 | C37: AIZA | D37: 6 | E37: ='Quote 33'!E14 -> 0 | F37: ='Quote 33'!G14 -> 765 | G37: Quote 33
A38: 34 | B38: 10/16/2026 | C38: AIZA | D38: 3 | E38: ='Quote 34'!E11 -> 0 | F38: ='Quote 34'!G11 -> 5238 | G38: Quote 34
A39: 35 | B39: 10/16/2026 | C39: AIZA | D39: 4 | E39: ='Quote 35'!E12 -> 0 | F39: ='Quote 35'!G12 -> 2508 | G39: Quote 35
A40: 36 | B40: 10/17/2026 | C40: AIZA | D40: 13 | E40: ='Quote 36'!E21 -> 0 | F40: ='Quote 36'!G21 -> 21528 | G40: Quote 36
A41: 37 | B41: 10/17/2026 | C41: AIZA | D41: 14 | E41: ='Quote 37'!E22 -> 0 | F41: ='Quote 37'!G22 -> 44795 | G41: Quote 37
...

Sheet Quote 01
A1: Fanvill Hardware Cabalwan | G1: PRICE QUOTE
A2: CABAL-AWAN TACLOBAN
A4: Name / Address | D4: Rep | E4: Project | F4: Date | G4: Quote #
A5: FANVILL CABALAWAN. | D5: AIZA | F5: 9/28/2026 | G5: 01
A7: Qty | B7: U/M | C7: Item | D7: Unit Capital | E7: Total Capital | F7: Unit Price | G7: Total Selling Price
A8: 170 | C8: C-Purlins 2x4 1.2mm | E8: =IF(ISNUMBER(D8), A8*D8, "") | F8: 775 | G8: =A8*F8 -> 131750
A9: 12 | B9: pc | C9: GI PIPE S-40 #3/4 | E9: =IF(ISNUMBER(D9), A9*D9, "") | F9: 775 | G9: =A9*F9 -> 9300
A10: 1 | C10: GI Pipe S-40 3/4 Samurai | E10: =IF(ISNUMBER(D10), A10*D10, "") | F10: 580 | G10: =A10*F10 -> 580
A11: 21 | C11: Plain Bar 16mm | E11: =IF(ISNUMBER(D11), A11*D11, "") | F11: 475 | G11: =A11*F11 -> 9975
A12: 7 | C12: I-Bar (6mm) | E12: =IF(ISNUMBER(D12), A12*D12, "") | F12: 650 | G12: =A12*F12 -> 4550
A13: 1 | C13: T-Bar | E13: =IF(ISNUMBER(D13), A13*D13, "") | F13: 285 | G13: =A13*F13 -> 285
A14: 1 | B14: pc | C14: 6mm x 2-1/2 Angle Bar (BROWN) | E14: =IF(ISNUMBER(D14), A14*D14, "") | F14: 2050 | G14: =A14*F14 -> 2050
A15: 1 | B15: pc | C15: 6mm x 3 Angle Bar (BROWN) | E15: =IF(ISNUMBER(D15), A15*D15, "") | F15: 2500 | G15: =A15*F15 -> 2500
A16: 1 | C16: Polycarbonate DF Asstd. 4x8x6mm | E16: =IF(ISNUMBER(D16), A16*D16, "") | F16: 1070 | G16: =A16*F16 -> 1070
A17: 12 | C17: Island Paint QDE Pink (Gal) | E17: =IF(ISNUMBER(D17), A17*D17, "") | F17: 615 | G17: =A17*F17 -> 7380
A18: 4 | C18: Island Paint QDE Nile Green (Gl | E18: =IF(ISNUMBER(D18), A18*D18, "") | F18: 570 | G18: =A18*F18 -> 2280
A19: 9 | C19: Island Paint QDE Int'l Red(gln) | E19: =IF(ISNUMBER(D19), A19*D19, "") | F19: 595 | G19: =A19*F19 -> 5355
A20: 3 | C20: Island Paint QDE Signal Red Gal | E20: =IF(ISNUMBER(D20), A20*D20, "") | F20: 625 | G20: =A20*F20 -> 1875
A21: 8 | C21: Island Paint E/Primer Red Ox GL | E21: =IF(ISNUMBER(D21), A21*D21, "") | F21: 750 | G21: =A21*F21 -> 6000
A22: 12 | C22: STAR ELASTOMER Red Balm (Gal.) | E22: =IF(ISNUMBER(D22), A22*D22, "") | F22: 700 | G22: =A22*F22 -> 8400
A23: 4 | C23: ROOFKOTE BAGUIO GREEN | E23: =IF(ISNUMBER(D23), A23*D23, "") | F23: 750 | G23: =A23*F23 -> 3000
A24: 8 | C24: ROOFKOTE NUT BROWN | E24: =IF(ISNUMBER(D24), A24*D24, "") | F24: 640 | G24: =A24*F24 -> 5120
A25: 4 | C25: ROOFKOTE CLEAR BLUE | E25: =IF(ISNUMBER(D25), A25*D25, "") | F25: 790 | G25: =A25*F25 -> 3160
A26: 4 | C26: Boysen Acrytex Cast (GLn) | E26: =IF(ISNUMBER(D26), A26*D26, "") | F26: 660 | G26: =A26*F26 -> 2640
A27: 6 | C27: Clear Gloss Lacquer (GLN) | E27: =IF(ISNUMBER(D27), A27*D27, "") | F27: 555 | G27: =A27*F27 -> 3330
... A56: 4760 | C56: Tex Screw for Wood 2-1/2 | E56: =IF(ISNUMBER(D56), A56*D56, "") | F56: 2 | G56: =A56*F56 -> 9520
A57: 176 | B57: kg | C57: Finishing Nails #1 | E57: =IF(ISNUMBER(D57), A57*D57, "") | F57: 90 | G57: =A57*F57 -> 15840
A58: 22 | B58: kg | C58: Finishing Nails #2-1/2 | E58: =IF(ISNUMBER(D58), A58*D58, "") | F58: 90 | G58: =A58*F58 -> 1980
A59: 110 | B59: kg | C59: Concrete Nails # 1 | E59: =IF(ISNUMBER(D59), A59*D59, "") | F59: 100 | G59: =A59*F59 -> 11000
A60: 110 | B60: kg | C60: Concrete Nails # 1-1/2 | E60: =IF(ISNUMBER(D60), A60*D60, "") | F60: 100 | G60: =A60*F60 -> 11000
A61: 132 | B61: kg | C61: Concrete Nails #2 | E61: =IF(ISNUMBER(D61), A61*D61, "") | F61: 100 | G61: =A61*F61 -> 13200
A62: 22 | B62: kg | C62: Common Nails # 5 | E62: =IF(ISNUMBER(D62), A62*D62, "") | F62: 80 | G62: =A62*F62 -> 1760
A63: 20 | C63: LAMCO Duplex Strainer | E63: =IF(ISNUMBER(D63), A63*D63, "") | F63: 110 | G63: =A63*F63 -> 2200
C64: Total | E64: =SUM(E8:E63) -> 0 | G64: =SUM(G8:G63) -> 398960

Sheet Quote 02
A1: Fanvill Hardware Cabalwan | G1: PRICE QUOTE
A2: CABAL-AWAN TACLOBAN
A4: Name / Address | D4: Rep | E4: Project | F4: Date | G4: Quote #
A5: FANVILL CABALAWAN. | D5: AIZA | F5: 9/28/2026 | G5: 02
A7: Qty | B7: U/M | C7: Item | D7: Unit Capital | E7: Total Capital | F7: Unit Price | G7: Total Selling Price
A8: 2 | C8: Angle Valve LAMCO54035 | E8: =IF(ISNUMBER(D8), A8*D8, "") | F8: 365 | G8: =A8*F8 -> 730
A9: 13 | C9: Foot Bolt AMERILOCK S/S | E9: =IF(ISNUMBER(D9), A9*D9, "") | F9: 270 | G9: =A9*F9 -> 3510
A10: 2 | C10: HASP Lock Amerilock #4 | E10: =IF(ISNUMBER(D10), A10*D10, "") | F10: 160 | G10: =A10*F10 -> 320
A11: 2 | C11: Hasp Lock #4 PH | E11: =IF(ISNUMBER(D11), A11*D11, "") | F11: 190 | G11: =A11*F11 -> 380
A12: 3 | C12: Sink Faucet LAMCO 62234 | E12: =IF(ISNUMBER(D12), A12*D12, "") | F12: 545 | G12: =A12*F12 -> 1635
A13: 1 | C13: Angle Valve LAMCO54028 | E13: =IF(ISNUMBER(D13), A13*D13, "") | F13: 240 | G13: =A13*F13 -> 240
A14: 1 | C14: SALE Shower Head SHARK SF2527 | E14: =IF(ISNUMBER(D14), A14*D14, "") | F14: 195 | G14: =A14*F14 -> 195
A15: 7 | C15: Hook & Eye #2-1/2 Jose | E15: =IF(ISNUMBER(D15), A15*D15, "") | F15: 15 | G15: =A15*F15 -> 105
A16: 5 | C16: Hook & Eye #2 Jose | E16: =IF(ISNUMBER(D16), A16*D16, "") | F16: 10 | G16: =A16*F16 -> 50
A17: 4 | C17: Hook & Eye #4 Jose | E17: =IF(ISNUMBER(D17), A17*D17, "") | F17: 30 | G17: =A17*F17 -> 120
A18: 1 | C18: Plumb Bob 200g | E18: =IF(ISNUMBER(D18), A18*D18, "") | F18: 100 | G18: =A18*F18 -> 100
A19: 2 | C19: Plumb Bob 250g | E19: =IF(ISNUMBER(D19), A19*D19, "") | F19: 115 | G19: =A19*F19 -> 230
... A34: 12 | C34: Barrel Bolt S/S DH 2" | E34: =IF(ISNUMBER(D34), A34*D34, "") | F34: 75 | G34: =A34*F34 -> 900
C35: Total | E35: =SUM(E8:E34) -> 0 | G35: =SUM(G8:G34) -> 17590

Sheet Quote 03
A1: Fanvill Hardware Cabalwan | G1: PRICE QUOTE
A2: CABAL-AWAN TACLOBAN
A4: Name / Address | D4: Rep | E4: Project | F4: Date | G4: Quote #
A5: FANVILL CABALAWAN. | D5: AIZA | F5: 9/28/2026 | G5: 03
A7: Qty | B7: U/M | C7: Item | D7: Unit Capital | E7: Total Capital | F7: Unit Price | G7: Total Selling Price
A8: 2 | C8: Lavatory Faucet Shark SF2408 | E8: =IF(ISNUMBER(D8), A8*D8, "") | F8: 800 | G8: =A8*F8 -> 1600
A9: 5 | C9: Soldering Lead YESTAR set | E9: =IF(ISNUMBER(D9), A9*D9, "") | F9: 165 | G9: =A9*F9 -> 825
A10: 1 | C10: Lock Installation Kit HD | E10: =IF(ISNUMBER(D10), A10*D10, "") | F10: 230 | G10: =A10*F10 -> 230
A11: 1 | C11: LPG Hose 1.5m KEMA | E11: =IF(ISNUMBER(D11), A11*D11, "") | F11: 105 | G11: =A11*F11 -> 105
A12: 2 | C12: PVC WATER JAG Faucet ROSCO 3/8 | E12: =IF(ISNUMBER(D12), A12*D12, "") | F12: 45 | G12: =A12*F12 -> 90
A13: 3 | C13: Angle Valve 3-Way PH | E13: =IF(ISNUMBER(D13), A13*D13, "") | F13: 300 | G13: =A13*F13 -> 900
A14: 24 | C14: Barrel Bolt Advance 3 | E14: =IF(ISNUMBER(D14), A14*D14, "") | F14: 20 | G14: =A14*F14 -> 480
A15: 36 | C15: Barrel Bolt Advance 2-1/2 | E15: =IF(ISNUMBER(D15), A15*D15, "") | F15: 25 | G15: =A15*F15 -> 900
A16: 96 | C16: Barrel Bolt Advance 1 1/2 | E16: =IF(ISNUMBER(D16), A16*D16, "") | F16: 15 | G16: =A16*F16 -> 1440
C17: Total | E17: =SUM(E8:E16) -> 0 | G17: =SUM(G8:G16) -> 6570

Sheet Quote 04
A1: Fanvill Hardware Cabalwan | G1: PRICE QUOTE
A2: CABAL-AWAN TACLOBAN
A4: Name / Address | D4: Rep | E4: Project | F4: Date | G4: Quote #
A5: FANVILL CABALAWAN. | D5: AIZA | F5: 9/28/2026 | G5: 04
A7: Qty | B7: U/M | C7: Item | D7: Unit Capital | E7: Total Capital | F7: Unit Price | G7: Total Selling Price
A8: 3 | C8: Lav. P-Trap 1-1/2 (Lamco28010) | E8: =IF(ISNUMBER(D8), A8*D8, "") | F8: 485 | G8: =A8*F8 -> 1455
A9: 4 | C9: SALE Gooseneck SUNRISE1321/1312 | E9: =IF(ISNUMBER(D9), A9*D9, "") | F9: 370 | G9: =A9*F9 -> 1480
A10: 13 | C10: Soldering Iron GF 40w | E10: =IF(ISNUMBER(D10), A10*D10, "") | F10: 145 | G10: =A10*F10 -> 1885
A11: 1 | C11: Soldering Iron 30W | E11: =IF(ISNUMBER(D11), A11*D11, "") | F11: 85 | G11: =A11*F11 -> 85
A12: 12 | C12: SALE Check Valve #3/4 SW | E12: =IF(ISNUMBER(D12), A12*D12, "") | F12: 425 | G12: =A12*F12 -> 5100
A13: 1 | C13: SALE Check Valve #1/2 SW | E13: =IF(ISNUMBER(D13), A13*D13, "") | F13: 285 | G13: =A13*F13 -> 285
A14: 1 | C14: SALE Check Valve #1 SW | E14: =IF(ISNUMBER(D14), A14*D14, "") | F14: 570 | G14: =A14*F14 -> 570
A15: 1 | C15: Combination Wrench #22 | E15: =IF(ISNUMBER(D15), A15*D15, "") | F15: 0 | G15: =A15*F15 -> 0
A16: 2 | C16: Combination Wrench #25 | E16: =IF(ISNUMBER(D16), A16*D16, "") | G16: =A16*F16 -> 0
A17: 7 | C17: Combination Wrench #19 THOR | E17: =IF(ISNUMBER(D17), A17*D17, "") | F17: 210 | G17: =A17*F17 -> 1470
A18: 1 | C18: Combination Wrench #9 | E18: =IF(ISNUMBER(D18), A18*D18, "") | F18: 45 | G18: =A18*F18 -> 45
C19: Total | E19: =SUM(E8:E18) -> 0 | G19: =SUM(G8:G18) -> 12375

Sheet Quote 05
A1: Fanvill Hardware Cabalwan | G1: PRICE QUOTE
A2: CABAL-AWAN TACLOBAN
A4: Name / Address | D4: Rep | E4: Project | F4: Date | G4: Quote #
A5: FANVILL CABALAWAN. | D5: AIZA | F5: 9/28/2026 | G5: 05
A7: Qty | B7: U/M | C7: Item | D7: Unit Capital | E7: Total Capital | F7: Unit Price | G7: Total Selling Price
A8: 11 | C8: LUX QDE Med. Brown | E8: =IF(ISNUMBER(D8), A8*D8, "") | F8: 35 | G8: =A8*F8 -> 385
A9: 10 | C9: LUX QDE Aluminum | E9: =IF(ISNUMBER(D9), A9*D9, "") | F9: 45 | G9: =A9*F9 -> 450
A10: 4 | C10: LUX QDE White | E10: =IF(ISNUMBER(D10), A10*D10, "") | F10: 30 | G10: =A10*F10 -> 120
A11: 6 | C11: LUX QDE Royal Blue | E11: =IF(ISNUMBER(D11), A11*D11, "") | F11: 30 | G11: =A11*F11 -> 180
A12: 3 | C12: LUX QDE V. Red | E12: =IF(ISNUMBER(D12), A12*D12, "") | F12: 30 | G12: =A12*F12 -> 90
A13: 1 | C13: LUX QDE Med. Yellow | E13: =IF(ISNUMBER(D13), A13*D13, "") | F13: 30 | G13: =A13*F13 -> 30
A14: 2 | C14: Boysen OTC Bulitine Red (1/4) | E14: =IF(ISNUMBER(D14), A14*D14, "") | F14: 140 | G14: =A14*F14 -> 280
A15: 2 | C15: Boysen OTC Raw Sienna (1/4) | E15: =IF(ISNUMBER(D15), A15*D15, "") | F15: 85 | G15: =A15*F15 -> 170
A16: 2 | C16: Island OTC Bulletin Red (1/4) | E16: =IF(ISNUMBER(D16), A16*D16, "") | F16: 120 | G16: =A16*F16 -> 240
A17: 6 | C17: Island OTC Raw Sienna (1/4) | E17: =IF(ISNUMBER(D17), A17*D17, "") | F17: 75 | G17: =A17*F17 -> 450
A18: 3 | C18: Island LTC Burnt Sienna (1/4) | E18: =IF(ISNUMBER(D18), A18*D18, "") | F18: 65 | G18: =A18*F18 -> 195
C19: Total | E19: =SUM(E8:E18) -> 0 | G19: =SUM(G8:G18) -> 2590

Sheet Quote 06
A1: Fanvill Hardware Cabalwan | G1: PRICE QUOTE
A2: CABAL-AWAN TACLOBAN
A4: Name / Address | D4: Rep | E4: Project | F4: Date | G4: Quote #
A5: FANVILL CABALAWAN. | D5: AIZA | F5: 9/30/2026 | G5: 06
A7: Qty | B7: U/M | C7: Item | D7: Unit Capital | E7: Total Capital | F7: Unit Price | G7: Total Selling Price
A8: 40 | C8: Hose Clamp #3 1HOLE | E8: =IF(ISNUMBER(D8), A8*D8, "") | F8: 65 | G8: =A8*F8 -> 2600
A9: 37 | C9: Hose Clamp #2 1HOLE | E9: =IF(ISNUMBER(D9), A9*D9, "") | F9: 35 | G9: =A9*F9 -> 1295
A10: 11 | C10: Hose Clamp #1 1HOLE | E10: =IF(ISNUMBER(D10), A10*D10, "") | F10: 15 | G10: =A10*F10 -> 165
A11: 41 | C11: Hose Clamp #3/4 1HOLE | E11: =IF(ISNUMBER(D11), A11*D11, "") | F11: 10 | G11: =A11*F11 -> 410
A12: 58 | C12: Hose Clamp 3/4 Double Hole | E12: =IF(ISNUMBER(D12), A12*D12, "") | F12: 15 | G12: =A12*F12 -> 870
A13: 64 | C13: Catches Magnetic BIG | E13: =IF(ISNUMBER(D13), A13*D13, "") | F13: 15 | G13: =A13*F13 -> 960
A14: 62 | C14: Catches Magnetic SMALL | E14: =IF(ISNUMBER(D14), A14*D14, "") | F14: 10 | G14: =A14*F14 -> 620
A15: 64 | C15: Catches Roller | E15: =IF(ISNUMBER(D15), A15*D15, "") | F15: 10 | G15: =A15*F15 -> 640
A16: 4 | C16: Hose Clamp #1/2 1HOLE | E16: =IF(ISNUMBER(D16), A16*D16, "") | F16: 10 | G16: =A16*F16 -> 40
A17: 96 | C17: DYNA BOLT 5/16 | E17: =IF(ISNUMBER(D17), A17*D17, "") | F17: 25 | G17: =A17*F17 -> 2400
A18: 114 | C18: DYNA BOLT 1/4 | E18: =IF(ISNUMBER(D18), A18*D18, "") | F18: 15 | G18: =A18*F18 -> 1710
A19: 3 | C19: DYNA BOLT 1/2 | E19: =IF(ISNUMBER(D19), A19*D19, "") | F19: 35 | G19: =A19*F19 -> 105
... A22: 7 | C22: Alligator Clip Big | E22: =IF(ISNUMBER(D22), A22*D22, "") | F22: 25 | G22: =A22*F22 -> 175
C23: Total | E23: =SUM(E8:E22) -> 0 | G23: =SUM(G8:G22) -> 16310

Sheet Quote 07
A1: Fanvill Hardware Cabalwan | G1: PRICE QUOTE
A2: CABAL-AWAN TACLOBAN
A4: Name / Address | D4: Rep | E4: Project | F4: Date | G4: Quote #
A5: FANVILL CABALAWAN. | D5: AIZA | F5: 9/30/2026 | G5: 07
A7: Qty | B7: U/M | C7: Item | D7: Unit Capital | E7: Total Capital | F7: Unit Price | G7: Total Selling Price
A8: 37 | C8: Entrance Cap 3/4 | E8: =IF(ISNUMBER(D8), A8*D8, "") | F8: 50 | G8: =A8*F8 -> 1850
A9: 32 | C9: Entrance Cap 1/2 | E9: =IF(ISNUMBER(D9), A9*D9, "") | F9: 45 | G9: =A9*F9 -> 1440
A10: 30 | C10: PVC Hose Coupling 5/8 Set | E10: =IF(ISNUMBER(D10), A10*D10, "") | F10: 60 | G10: =A10*F10 -> 1800
A11: 3 | C11: Plumb Bob 150g SILVER | E11: =IF(ISNUMBER(D11), A11*D11, "") | F11: 60 | G11: =A11*F11 -> 180
A12: 31 | C12: SALE PVC Hose Coupling #1/2 Set | E12: =IF(ISNUMBER(D12), A12*D12, "") | F12: 42 | G12: =A12*F12 -> 1302
A13: 10 | C13: SALE Hose Coupling #1/2 Metal | E13: =IF(ISNUMBER(D13), A13*D13, "") | F13: 34 | G13: =A13*F13 -> 340
A14: 11 | C14: SALE Hose Coupling # 5/8 Metal | E14: =IF(ISNUMBER(D14), A14*D14, "") | F14: 24 | G14: =A14*F14 -> 264
A15: 6 | C15: Pig Drinker Assorted | E15: =IF(ISNUMBER(D15), A15*D15, "") | F15: 60 | G15: =A15*F15 -> 360
A16: 5 | C16: GI Nipple 1x6 | E16: =IF(ISNUMBER(D16), A16*D16, "") | F16: 75 | G16: =A16*F16 -> 375
A17: 12 | C17: GI Nipple 1x8 | E17: =IF(ISNUMBER(D17), A17*D17, "") | F17: 85 | G17: =A17*F17 -> 1020
A18: 9 | C18: GI Nipple 1x10 | E18: =IF(ISNUMBER(D18), A18*D18, "") | F18: 105 | G18: =A18*F18 -> 945
A19: 4 | C19: GI Nipple 1x4 | E19: =IF(ISNUMBER(D19), A19*D19, "") | F19: 45 | G19: =A19*F19 -> 180
... A32: 55 | C32: Steel Casement Handle | E32: =IF(ISNUMBER(D32), A32*D32, "") | F32: 60 | G32: =A32*F32 -> 3300
C33: Total | E33: =SUM(E8:E32) -> 0 | G33: =SUM(G8:G32) -> 23946

Sheet Quote 08
A1: Fanvill Hardware Cabalwan | G1: PRICE QUOTE
A2: CABAL-AWAN TACLOBAN
A4: Name / Address | D4: Rep | E4: Project | F4: Date | G4: Quote #
A5: FANVILL CABALAWAN. | D5: AIZA | F5: 10/1/2026 | G5: 08
A7: Qty | B7: U/M | C7: Item | D7: Unit Capital | E7: Total Capital | F7: Unit Price | G7: Total Selling Price
A8: 3 | C8: Handsaw YESTAR 20" | E8: =IF(ISNUMBER(D8), A8*D8, "") | F8: 220 | G8: =A8*F8 -> 660
A9: 9 | C9: Compass Saw YESTAR #16 | E9: =IF(ISNUMBER(D9), A9*D9, "") | F9: 150 | G9: =A9*F9 -> 1350
A10: 18 | C10: Carborandum #8 | E10: =IF(ISNUMBER(D10), A10*D10, "") | F10: 120 | G10: =A10*F10 -> 2160
A11: 19 | C11: Carburandum #6 | E11: =IF(ISNUMBER(D11), A11*D11, "") | F11: 80 | G11: =A11*F11 -> 1520
C12: Total | E12: =SUM(E8:E11) -> 0 | G12: =SUM(G8:G11) -> 5690

Sheet Quote 09
A1: Fanvill Hardware Cabalwan | G1: PRICE QUOTE
A2: CABAL-AWAN TACLOBAN
A4: Name / Address | D4: Rep | E4: Project | F4: Date | G4: Quote #
A5: FANVILL CABALAWAN. | D5: AIZA | F5: 10/1/2026 | G5: 09
A7: Qty | B7: U/M | C7: Item | D7: Unit Capital | E7: Total Capital | F7: Unit Price | G7: Total Selling Price
A8: 7 | C8: Doormer 1/2 HD | E8: =IF(ISNUMBER(D8), A8*D8, "") | F8: 400 | G8: =A8*F8 -> 2800
A9: 9 | C9: Doormer 7/16 HD | E9: =IF(ISNUMBER(D9), A9*D9, "") | F9: 310 | G9: =A9*F9 -> 2790
A10: 2 | C10: Doormer 5/8 HD | E10: =IF(ISNUMBER(D10), A10*D10, "") | F10: 1500 | G10: =A10*F10 -> 3000
A11: 32 | C11: DEWALT Drillbit 1/2 | E11: =IF(ISNUMBER(D11), A11*D11, "") | F11: 460 | G11: =A11*F11 -> 14720
A12: 3 | C12: Spool Insulator | E12: =IF(ISNUMBER(D12), A12*D12, "") | F12: 50 | G12: =A12*F12 -> 150
A13: 3 | C13: Screw Insulator(B) | E13: =IF(ISNUMBER(D13), A13*D13, "") | F13: 35 | G13: =A13*F13 -> 105
A14: 3 | C14: Screw Insulator(S) | E14: =IF(ISNUMBER(D14), A14*D14, "") | F14: 15 | G14: =A14*F14 -> 45
A15: 50 | C15: EMT Coupling 1/2 | E15: =IF(ISNUMBER(D15), A15*D15, "") | F15: 15 | G15: =A15*F15 -> 750
A16: 64 | C16: EMT Coupling 3/4 | E16: =IF(ISNUMBER(D16), A16*D16, "") | F16: 25 | G16: =A16*F16 -> 1600
A17: 2 | C17: Wood Chisel # 3/4 China | E17: =IF(ISNUMBER(D17), A17*D17, "") | F17: 55 | G17: =A17*F17 -> 110
A18: 4 | C18: Lavatory Hose 1/2X1/2X12 SUNRIS | E18: =IF(ISNUMBER(D18), A18*D18, "") | F18: 70 | G18: =A18*F18 -> 280
A19: 2 | C19: Lavatory Hose #1/2X1/2X12 SHARK | E19: =IF(ISNUMBER(D19), A19*D19, "") | F19: 95 | G19: =A19*F19 -> 190
... A32: 7 | C32: Door Spring #6 | E32: =IF(ISNUMBER(D32), A32*D32, "") | F32: 30 | G32: =A32*F32 -> 210
C33: Total | E33: =SUM(E8:E32) -> 0 | G33: =SUM(G8:G32) -> 35500

Sheet Quote 10
A1: Fanvill Hardware Cabalwan | G1: PRICE QUOTE
A2: CABAL-AWAN TACLOBAN
A4: Name / Address | D4: Rep | E4: Project | F4: Date | G4: Quote #
A5: FANVILL CABALAWAN. | D5: AIZA | F5: 10/2/2026 | G5: 10
A7: Qty | B7: U/M | C7: Item | D7: Unit Capital | E7: Total Capital | F7: Unit Price | G7: Total Selling Price
A8: 7 | C8: PE Male Adaptor 1/2 | E8: =IF(ISNUMBER(D8), A8*D8, "") | F8: 50 | G8: =A8*F8 -> 350
A9: 2 | C9: PE Elbow 3/4 | E9: =IF(ISNUMBER(D9), A9*D9, "") | F9: 85 | G9: =A9*F9 -> 170
A10: 2 | C10: PE Coupling 3/4 | E10: =IF(ISNUMBER(D10), A10*D10, "") | F10: 90 | G10: =A10*F10 -> 180
A11: 5 | C11: PE Male Adaptor 3/4 | E11: =IF(ISNUMBER(D11), A11*D11, "") | F11: 80 | G11: =A11*F11 -> 400
A12: 5 | C12: SALE PNS Long Elbow 1 | E12: =IF(ISNUMBER(D12), A12*D12, "") | F12: 27 | G12: =A12*F12 -> 135
A13: 36 | C13: SALE PNS Short Elbow 3/4 | E13: =IF(ISNUMBER(D13), A13*D13, "") | F13: 14 | G13: =A13*F13 -> 504
A14: 24 | C14: PNS Coupling 3/4 | E14: =IF(ISNUMBER(D14), A14*D14, "") | F14: 15 | G14: =A14*F14 -> 360
A15: 1 | C15: PNS Short Elbow 1/2 | E15: =IF(ISNUMBER(D15), A15*D15, "") | F15: 15 | G15: =A15*F15 -> 15
A16: 1 | C16: PNS Long Elbow 1/2 | E16: =IF(ISNUMBER(D16), A16*D16, "") | F16: 20 | G16: =A16*F16 -> 20
A17: 1 | C17: PNS Coupling 1/2 | E17: =IF(ISNUMBER(D17), A17*D17, "") | F17: 10 | G17: =A17*F17 -> 10
A18: 4 | C18: PE Tee 3/4 | E18: =IF(ISNUMBER(D18), A18*D18, "") | F18: 120 | G18: =A18*F18 -> 480
A19: 1 | C19: PE Elbow 1 | E19: =IF(ISNUMBER(D19), A19*D19, "") | F19: 105 | G19: =A19*F19 -> 105
... A23: 50 | C23: Poly Connector 1/2 | E23: =IF(ISNUMBER(D23), A23*D23, "") | F23: 10 | G23: =A23*F23 -> 500
C24: Total | E24: =SUM(E8:E23) -> 0 | G24: =SUM(G8:G23) -> 5229

Sheet Quote 11
A1: Fanvill Hardware Cabalwan | G1: PRICE QUOTE
A2: CABAL-AWAN TACLOBAN
A4: Name / Address | D4: Rep | E4: Project | F4: Date | G4: Quote #
A5: FANVILL CABALAWAN. | D5: AIZA | F5: 10/2/2026 | G5: 11
A7: Qty | B7: U/M | C7: Item | D7: Unit Capital | E7: Total Capital | F7: Unit Price | G7: Total Selling Price
A8: 1 | C8: PE Coupling Red. 3/4x1/2 | E8: =IF(ISNUMBER(D8), A8*D8, "") | F8: 75 | G8: =A8*F8 -> 75
A9: 12 | C9: PE Female Adaptor 1/2 | E9: =IF(ISNUMBER(D9), A9*D9, "") | F9: 50 | G9: =A9*F9 -> 600
A10: 12 | C10: PE Elbow 1/2 | E10: =IF(ISNUMBER(D10), A10*D10, "") | F10: 80 | G10: =A10*F10 -> 960
A11: 16 | C11: PE Coupling 1/2 | E11: =IF(ISNUMBER(D11), A11*D11, "") | F11: 85 | G11: =A11*F11 -> 1360
A12: 34 | C12: PE Female Adaptor 3/4 | E12: =IF(ISNUMBER(D12), A12*D12, "") | F12: 65 | G12: =A12*F12 -> 2210
A13: 9 | C13: PE Tee 1/2 | E13: =IF(ISNUMBER(D13), A13*D13, "") | F13: 80 | G13: =A13*F13 -> 720
A14: 24 | C14: PVC Blue Coupling #1 1/4 | E14: =IF(ISNUMBER(D14), A14*D14, "") | F14: 25 | G14: =A14*F14 -> 600
A15: 2 | C15: PVC Blue Tee #1-1/4 P | E15: =IF(ISNUMBER(D15), A15*D15, "") | F15: 25 | G15: =A15*F15 -> 50
A16: 3 | C16: PVC Blue Male Adaptor #1-1/4 | E16: =IF(ISNUMBER(D16), A16*D16, "") | F16: 25 | G16: =A16*F16 -> 75
A17: 18 | C17: PVC Blue Female Adaptor #1-1/4 | E17: =IF(ISNUMBER(D17), A17*D17, "") | F17: 25 | G17: =A17*F17 -> 450
A18: 7 | C18: PVC Blue Union #1-1/4 | E18: =IF(ISNUMBER(D18), A18*D18, "") | F18: 125 | G18: =A18*F18 -> 875
A19: 6 | C19: PE Coupling 1 | E19: =IF(ISNUMBER(D19), A19*D19, "") | F19: 90 | G19: =A19*F19 -> 540
... A26: 4 | C26: PVC Blue Male Adaptor #2 | E26: =IF(ISNUMBER(D26), A26*D26, "") | F26: 40 | G26: =A26*F26 -> 160
C27: Total | E27: =SUM(E8:E26) -> 0 | G27: =SUM(G8:G26) -> 9530

Sheet Quote 12
A1: Fanvill Hardware Cabalwan | G1: PRICE QUOTE
A2: CABAL-AWAN TACLOBAN
A4: Name / Address | D4: Rep | E4: Project | F4: Date | G4: Quote #
A5: FANVILL CABALAWAN. | D5: AIZA | F5: 9/28/2026 | G5: 12
A7: Qty | B7: U/M | C7: Item | D7: Unit Capital | E7: Total Capital | F7: Unit Price | G7: Total Selling Price
A8: 9 | C8: Pylox Lazer #605 F-Green | E8: =IF(ISNUMBER(D8), A8*D8, "") | F8: 190 | G8: =A8*F8 -> 1710
A9: 2 | C9: Pylox Lazer #705 Gold | E9: =IF(ISNUMBER(D9), A9*D9, "") | F9: 160 | G9: =A9*F9 -> 320
A10: 3 | C10: Pylox Lazer #706 Flash Gold | E10: =IF(ISNUMBER(D10), A10*D10, "") | F10: 160 | G10: =A10*F10 -> 480
A11: 10 | C11: Pylox Lazer #601 F-Orange | E11: =IF(ISNUMBER(D11), A11*D11, "") | F11: 190 | G11: =A11*F11 -> 1900
A12: 3 | C12: Pylox Lazer #710 Solid Gold | E12: =IF(ISNUMBER(D12), A12*D12, "") | F12: 160 | G12: =A12*F12 -> 480
A13: 1 | C13: Pylox Lazer #01 Clear | E13: =IF(ISNUMBER(D13), A13*D13, "") | F13: 125 | G13: =A13*F13 -> 125
A14: 5 | C14: Bosny Polyurethane #1900 | E14: =IF(ISNUMBER(D14), A14*D14, "") | F14: 390 | G14: =A14*F14 -> 1950
A15: 8 | C15: Bosny Undercoat Rubberized B104 | E15: =IF(ISNUMBER(D15), A15*D15, "") | F15: 190 | G15: =A15*F15 -> 1520
C16: Total | E16: =SUM(E8:E15) -> 0 | G16: =SUM(G8:G15) -> 8485

Sheet Quote 13
A1: Fanvill Hardware Cabalwan | G1: PRICE QUOTE
A2: CABAL-AWAN TACLOBAN
A4: Name / Address | D4: Rep | E4: Project | F4: Date | G4: Quote #
A5: FANVILL CABALAWAN. | D5: AIZA | F5: 9/29/2026 | G5: 13
A7: Qty | B7: U/M | C7: Item | D7: Unit Capital | E7: Total Capital | F7: Unit Price | G7: Total Selling Price
A8: 5 | C8: ECOLINK Led 13w DL | E8: =IF(ISNUMBER(D8), A8*D8, "") | F8: 101 | G8: =A8*F8 -> 505
A9: 5 | C9: ECOLINK Led 11w DL | E9: =IF(ISNUMBER(D9), A9*D9, "") | F9: 78.29 | G9: =A9*F9 -> 391.45
A10: 6 | C10: ECOLINK Led 9w DL | E10: =IF(ISNUMBER(D10), A10*D10, "") | F10: 70 | G10: =A10*F10 -> 420
A11: 4 | C11: ECOLINK Led 7w DL | E11: =IF(ISNUMBER(D11), A11*D11, "") | F11: 60 | G11: =A11*F11 -> 240
A12: 5 | C12: ECOLINK Led 3w DL | E12: =IF(ISNUMBER(D12), A12*D12, "") | F12: 51.09 | G12: =A12*F12 -> 255.45
A13: 8 | C13: PHILIPS LED BULB 13W | E13: =IF(ISNUMBER(D13), A13*D13, "") | F13: 140 | G13: =A13*F13 -> 1120
A14: 8 | C14: PHILIPS LED BULB 11W | E14: =IF(ISNUMBER(D14), A14*D14, "") | F14: 120 | G14: =A14*F14 -> 960
A15: 9 | C15: PHILIPS LED BULB 9W | E15: =IF(ISNUMBER(D15), A15*D15, "") | F15: 100 | G15: =A15*F15 -> 900
A16: 6 | C16: PHILIPS LED BULB 7W | E16: =IF(ISNUMBER(D16), A16*D16, "") | F16: 90 | G16: =A16*F16 -> 540
A17: 7 | C17: PHILIPS LED BULB 3W | E17: =IF(ISNUMBER(D17), A17*D17, "") | F17: 70 | G17: =A17*F17 -> 490
A18: 5 | C18: KANTT Led Bulb 11W | E18: =IF(ISNUMBER(D18), A18*D18, "") | F18: 170 | G18: =A18*F18 -> 850
A19: 14 | C19: KANTT Led Bulb 7w | E19: =IF(ISNUMBER(D19), A19*D19, "") | F19: 145 | G19: =A19*F19 -> 2030
C20: Total | E20: =SUM(E8:E19) -> 0 | G20: =SUM(G8:G19) -> 8701.9

Sheet Quote 14
A1: Fanvill Hardware Cabalwan | G1: PRICE QUOTE
A2: CABAL-AWAN TACLOBAN
A4: Name / Address | D4: Rep | E4: Project | F4: Date | G4: Quote #
A5: FANVILL CABALAWAN. | D5: AIZA | F5: 9/29/2026 | G5: 14
A7: Qty | B7: U/M | C7: Item | D7: Unit Capital | E7: Total Capital | F7: Unit Price | G7: Total Selling Price
A8: 17 | C8: FSL Led Bulb 3W DL | E8: =IF(ISNUMBER(D8), A8*D8, "") | F8: 55 | G8: =A8*F8 -> 935
A9: 17 | C9: FSL Led Bulb 3W WW | E9: =IF(ISNUMBER(D9), A9*D9, "") | F9: 55 | G9: =A9*F9 -> 935
A10: 5 | C10: F/Fly Bulb 3U 23W | E10: =IF(ISNUMBER(D10), A10*D10, "") | F10: 140 | G10: =A10*F10 -> 700
A11: 53 | C11: SALE F/Fly Emergency Bulb 12wDL | E11: =IF(ISNUMBER(D11), A11*D11, "") | F11: 275 | G11: =A11*F11 -> 14575
A12: 4 | C12: SALE F/Fly Emergency Bulb 8w DL | E12: =IF(ISNUMBER(D12), A12*D12, "") | F12: 210 | G12: =A12*F12 -> 840
C13: Total | E13: =SUM(E8:E12) -> 0 | G13: =SUM(G8:G12) -> 17985

Sheet Quote 15
A1: Fanvill Hardware Cabalwan | G1: PRICE QUOTE
A2: CABAL-AWAN TACLOBAN
A4: Name / Address | D4: Rep | E4: Project | F4: Date | G4: Quote #
A5: FANVILL CABALAWAN. | D5: AIZA | F5: 10/1/2026 | G5: 15
A7: Qty | B7: U/M | C7: Item | D7: Unit Capital | E7: Total Capital | F7: Unit Price | G7: Total Selling Price
A8: 2 | C8: Electrode Holder 500A JacksonLD | E8: =IF(ISNUMBER(D8), A8*D8, "") | F8: 270 | G8: =A8*F8 -> 540
A9: 10 | C9: Cup Brush PH #350 TWISTED | E9: =IF(ISNUMBER(D9), A9*D9, "") | F9: 130 | G9: =A9*F9 -> 1300
A10: 2 | C10: Cup Brush (Twisted) | E10: =IF(ISNUMBER(D10), A10*D10, "") | F10: 115 | G10: =A10*F10 -> 230
A11: 3 | C11: Cup Brush (Plain) | E11: =IF(ISNUMBER(D11), A11*D11, "") | F11: 115 | G11: =A11*F11 -> 345
A12: 2 | C12: PVC Foot Valve #1T | E12: =IF(ISNUMBER(D12), A12*D12, "") | F12: 135 | G12: =A12*F12 -> 270
A13: 2 | C13: SALE Foot Valve #3/4 SW | E13: =IF(ISNUMBER(D13), A13*D13, "") | F13: 250 | G13: =A13*F13 -> 500
A14: 1 | C14: SALE Foot Valve SHARK 3/4 | E14: =IF(ISNUMBER(D14), A14*D14, "") | F14: 150 | G14: =A14*F14 -> 150
A15: 2 | C15: Foot Valve SHARK 1/2 | E15: =IF(ISNUMBER(D15), A15*D15, "") | F15: 150 | G15: =A15*F15 -> 300
A16: 1 | C16: Check Valve 1-1/4 Clayton | E16: =IF(ISNUMBER(D16), A16*D16, "") | F16: 270 | G16: =A16*F16 -> 270
A17: 1 | C17: SALE Check Valve #3/4 SW | E17: =IF(ISNUMBER(D17), A17*D17, "") | F17: 425 | G17: =A17*F17 -> 425
A18: 7 | C18: America Fuse 60A | E18: =IF(ISNUMBER(D18), A18*D18, "") | F18: 35 | G18: =A18*F18 -> 245
A19: 5 | C19: America Fuse 15A | E19: =IF(ISNUMBER(D19), A19*D19, "") | F19: 20 | G19: =A19*F19 -> 100
... A24: 49 | C24: Splitter 2-Way | E24: =IF(ISNUMBER(D24), A24*D24, "") | F24: 45 | G24: =A24*F24 -> 2205
C25: Total | E25: =SUM(E8:E24) -> 0 | G25: =SUM(G8:G24) -> 10247

Sheet Quote 16
A1: Fanvill Hardware Cabalwan | G1: PRICE QUOTE
A2: CABAL-AWAN TACLOBAN
A4: Name / Address | D4: Rep | E4: Project | F4: Date | G4: Quote #
A5: FANVILL CABALAWAN. | D5: AIZA | F5: 10/2/2026 | G5: 16
A7: Qty | B7: U/M | C7: Item | D7: Unit Capital | E7: Total Capital | F7: Unit Price | G7: Total Selling Price
A8: 4 | C8: Clear Gloss Lacquer (Bottle) | E8: =IF(ISNUMBER(D8), A8*D8, "") | F8: 55 | G8: =A8*F8 -> 220
A9: 10 | C9: Lacquer Flo (Btl) | E9: =IF(ISNUMBER(D9), A9*D9, "") | F9: 75 | G9: =A9*F9 -> 750
A10: 1 | C10: Paint Thinner LUX (Btl) | E10: =IF(ISNUMBER(D10), A10*D10, "") | F10: 70 | G10: =A10*F10 -> 70
A11: 1 | C11: NIPPON Varnish (Ltr) | E11: =IF(ISNUMBER(D11), A11*D11, "") | F11: 600 | G11: =A11*F11 -> 600
A12: 1 | C12: Timberguard Brown (Ltr) | E12: =IF(ISNUMBER(D12), A12*D12, "") | F12: 510 | G12: =A12*F12 -> 510
A13: 3 | C13: Timberguard Clear (Ltr) | E13: =IF(ISNUMBER(D13), A13*D13, "") | F13: 590 | G13: =A13*F13 -> 1770
C14: Total | E14: =SUM(E8:E13) -> 0 | G14: =SUM(G8:G13) -> 3920

Sheet Quote 17
A1: Fanvill Hardware Cabalwan | G1: PRICE QUOTE
A2: CABAL-AWAN TACLOBAN
A4: Name / Address | D4: Rep | E4: Project | F4: Date | G4: Quote #
A5: FANVILL CABALAWAN. | D5: AIZA | F5: 10/2/2026 | G5: 17
A7: Qty | B7: U/M | C7: Item | D7: Unit Capital | E7: Total Capital | F7: Unit Price | G7: Total Selling Price
A8: 12 | C8: PVC Blue Male Adaptor #1/2 | E8: =IF(ISNUMBER(D8), A8*D8, "") | F8: 15 | G8: =A8*F8 -> 180
A9: 52 | C9: PVC Blue Male Adaptor #3/4 | E9: =IF(ISNUMBER(D9), A9*D9, "") | F9: 15 | G9: =A9*F9 -> 780
A10: 35 | C10: PVC Blue Male Adaptor #1 | E10: =IF(ISNUMBER(D10), A10*D10, "") | F10: 20 | G10: =A10*F10 -> 700
A11: 29 | C11: PVC Blue Female Adaptor #1/2 | E11: =IF(ISNUMBER(D11), A11*D11, "") | F11: 15 | G11: =A11*F11 -> 435
A12: 49 | C12: PVC Blue Female Adaptor #3/4 | E12: =IF(ISNUMBER(D12), A12*D12, "") | F12: 20 | G12: =A12*F12 -> 980
A13: 6 | C13: PVC Blue Female Adaptor #1 | E13: =IF(ISNUMBER(D13), A13*D13, "") | F13: 20 | G13: =A13*F13 -> 120
A14: 21 | C14: PVC Blue Elbow #1/2 T | E14: =IF(ISNUMBER(D14), A14*D14, "") | F14: 15 | G14: =A14*F14 -> 315
A15: 23 | C15: PVC Blue Elbow #3/4 T | E15: =IF(ISNUMBER(D15), A15*D15, "") | F15: 15 | G15: =A15*F15 -> 345
A16: 10 | C16: PVC Blue Elbow #1 T | E16: =IF(ISNUMBER(D16), A16*D16, "") | F16: 20 | G16: =A16*F16 -> 200
A17: 4 | C17: PVC Blue Tee #1/2 T | E17: =IF(ISNUMBER(D17), A17*D17, "") | F17: 15 | G17: =A17*F17 -> 60
A18: 16 | C18: PVC Blue Elbow #1 P | E18: =IF(ISNUMBER(D18), A18*D18, "") | F18: 20 | G18: =A18*F18 -> 320
A19: 38 | C19: PVC Blue Elbow #1/2 P | E19: =IF(ISNUMBER(D19), A19*D19, "") | F19: 15 | G19: =A19*F19 -> 570
... A29: 2 | C29: Female Socket | E29: =IF(ISNUMBER(D29), A29*D29, "") | F29: 20 | G29: =A29*F29 -> 40
C30: Total | E30: =SUM(E8:E29) -> 0 | G30: =SUM(G8:G29) -> 8542.5

Sheet Quote 18
A1: Fanvill Hardware Cabalwan | G1: PRICE QUOTE
A2: CABAL-AWAN TACLOBAN
A4: Name / Address | D4: Rep | E4: Project | F4: Date | G4: Quote #
A5: FANVILL CABALAWAN. | D5: AIZA | F5: 10/6/2026 | G5: 18
A7: Qty | B7: U/M | C7: Item | D7: Unit Capital | E7: Total Capital | F7: Unit Price | G7: Total Selling Price
A8: 7 | C8: PPR PVC Brass Ball Valve #1 | E8: =IF(ISNUMBER(D8), A8*D8, "") | F8: 505 | G8: =A8*F8 -> 3535
A9: 3 | C9: PPR PVC Brass Ball Valve 3/4 | E9: =IF(ISNUMBER(D9), A9*D9, "") | F9: 425 | G9: =A9*F9 -> 1275
A10: 8 | C10: PPR PVC Brass Ball Valve 1/2 | E10: =IF(ISNUMBER(D10), A10*D10, "") | F10: 270 | G10: =A10*F10 -> 2160
A11: 9 | C11: PPR PVC Ball Valve 1/2 | E11: =IF(ISNUMBER(D11), A11*D11, "") | F11: 120 | G11: =A11*F11 -> 1080
A12: 5 | C12: PPR PVC Ball Valve #3/4 | E12: =IF(ISNUMBER(D12), A12*D12, "") | F12: 170 | G12: =A12*F12 -> 850
A13: 68 | C13: YESTAR Grinding Disc | E13: =IF(ISNUMBER(D13), A13*D13, "") | F13: 50 | G13: =A13*F13 -> 3400
A14: 10 | C14: Blank Plate ROYU | E14: =IF(ISNUMBER(D14), A14*D14, "") | F14: 30 | G14: =A14*F14 -> 300
A15: 9 | C15: SALE Rubber Socket B1T1 | E15: =IF(ISNUMBER(D15), A15*D15, "") | F15: 30 | G15: =A15*F15 -> 270
A16: 4 | C16: SALE PULL CHAIN SOCKET B1T1 | E16: =IF(ISNUMBER(D16), A16*D16, "") | F16: 60 | G16: =A16*F16 -> 240
A17: 7 | C17: SALE Trowel Cement # 7 | E17: =IF(ISNUMBER(D17), A17*D17, "") | F17: 40 | G17: =A17*F17 -> 280
A18: 8 | C18: Trowel Cement # 5 | E18: =IF(ISNUMBER(D18), A18*D18, "") | F18: 80 | G18: =A18*F18 -> 640
A19: 355 | C19: Tex Screw for Wood 2-1/2 | E19: =IF(ISNUMBER(D19), A19*D19, "") | F19: 2 | G19: =A19*F19 -> 710
... A23: 10 | C23: Cylindrical Hinges 3/8 | E23: =IF(ISNUMBER(D23), A23*D23, "") | F23: 20 | G23: =A23*F23 -> 200
C24: Total | E24: =SUM(E8:E23) -> 0 | G24: =SUM(G8:G23) -> 16106

Sheet Quote 19
A1: Fanvill Hardware Cabalwan | G1: PRICE QUOTE
A2: CABAL-AWAN TACLOBAN
A4: Name / Address | D4: Rep | E4: Project | F4: Date | G4: Quote #
A5: FANVILL CABALAWAN. | D5: AIZA | F5: 10/12/2026 | G5: 19
A7: Qty | B7: U/M | C7: Item | D7: Unit Capital | E7: Total Capital | F7: Unit Price | G7: Total Selling Price
A8: 11 | C8: Sandpaper #80 | E8: =IF(ISNUMBER(D8), A8*D8, "") | F8: 20 | G8: =A8*F8 -> 220
A9: 23 | C9: Sandpaper #150 | E9: =IF(ISNUMBER(D9), A9*D9, "") | F9: 20 | G9: =A9*F9 -> 460
A10: 29 | C10: Sandpaper #180 | E10: =IF(ISNUMBER(D10), A10*D10, "") | F10: 20 | G10: =A10*F10 -> 580
A11: 83 | C11: Sandpaper #220 | E11: =IF(ISNUMBER(D11), A11*D11, "") | F11: 20 | G11: =A11*F11 -> 1660
A12: 32 | C12: Sandpaper #1500 | E12: =IF(ISNUMBER(D12), A12*D12, "") | F12: 20 | G12: =A12*F12 -> 640
A13: 94 | C13: Sandpaper # 240 | E13: =IF(ISNUMBER(D13), A13*D13, "") | F13: 20 | G13: =A13*F13 -> 1880
A14: 175 | C14: Sandpaper # 600 | E14: =IF(ISNUMBER(D14), A14*D14, "") | F14: 20 | G14: =A14*F14 -> 3500
A15: 88 | C15: Sandpaper # 280 | E15: =IF(ISNUMBER(D15), A15*D15, "") | F15: 20 | G15: =A15*F15 -> 1760
A16: 66 | C16: Sandpaper #120 | E16: =IF(ISNUMBER(D16), A16*D16, "") | F16: 20 | G16: =A16*F16 -> 1320
A17: 49 | C17: Sandpaper #400 | E17: =IF(ISNUMBER(D17), A17*D17, "") | F17: 20 | G17: =A17*F17 -> 980
A18: 88 | C18: Sandpaper #1000 | E18: =IF(ISNUMBER(D18), A18*D18, "") | F18: 20 | G18: =A18*F18 -> 1760
A19: 100 | C19: Sandpaper #60 | E19: =IF(ISNUMBER(D19), A19*D19, "") | F19: 20 | G19: =A19*F19 -> 2000
C20: Total | E20: =SUM(E8:E19) -> 0 | G20: =SUM(G8:G19) -> 16760

Sheet Quote 20
A1: Fanvill Hardware Cabalwan | G1: PRICE QUOTE
A2: CABAL-AWAN TACLOBAN
A4: Name / Address | D4: Rep | E4: Project | F4: Date | G4: Quote #
A5: FANVILL CABALAWAN. | D5: AIZA | F5: 10/7/2026 | G5: 20
A7: Qty | B7: U/M | C7: Item | D7: Unit Capital | E7: Total Capital | F7: Unit Price | G7: Total Selling Price
A8: 71 | C8: SALE PPR Gate Valve 1 | E8: =IF(ISNUMBER(D8), A8*D8, "") | F8: 477.5 | G8: =A8*F8 -> 33902.5
C9: Total | E9: =SUM(E8:E8) -> 0 | G9: =SUM(G8:G8) -> 33902.5

Sheet Quote 21
A1: Fanvill Hardware Cabalwan | G1: PRICE QUOTE
A2: CABAL-AWAN TACLOBAN
A4: Name / Address | D4: Rep | E4: Project | F4: Date | G4: Quote #
A5: FANVILL CABALAWAN. | D5: AIZA | F5: 10/7/2026 | G5: 21
A7: Qty | B7: U/M | C7: Item | D7: Unit Capital | E7: Total Capital | F7: Unit Price | G7: Total Selling Price
A8: 29 | C8: PPR Female Adaptor 1/2 | E8: =IF(ISNUMBER(D8), A8*D8, "") | F8: 100 | G8: =A8*F8 -> 2900
A9: 13 | C9: Gate Valve 1/2 | E9: =IF(ISNUMBER(D9), A9*D9, "") | F9: 225 | G9: =A9*F9 -> 2925
A10: 110 | C10: SALE PPR Gate Valve 3/4 | E10: =IF(ISNUMBER(D10), A10*D10, "") | F10: 350 | G10: =A10*F10 -> 38500
C11: Total | E11: =SUM(E8:E10) -> 0 | G11: =SUM(G8:G10) -> 44325

Sheet Quote 22
A1: Fanvill Hardware Cabalwan | G1: PRICE QUOTE
A2: CABAL-AWAN TACLOBAN
A4: Name / Address | D4: Rep | E4: Project | F4: Date | G4: Quote #
A5: FANVILL CABALAWAN. | D5: AIZA | F5: 10/5/2026 | G5: 22
A7: Qty | B7: U/M | C7: Item | D7: Unit Capital | E7: Total Capital | F7: Unit Price | G7: Total Selling Price
A8: 3 | C8: GI Faucet JOSE HB 9155 | E8: =IF(ISNUMBER(D8), A8*D8, "") | F8: 145 | G8: =A8*F8 -> 435
A9: 1 | C9: Lavatory X-Faucet (MAXTEN) | E9: =IF(ISNUMBER(D9), A9*D9, "") | F9: 75 | G9: =A9*F9 -> 75
A10: 8 | C10: SALE GI Faucet PricePfister P/B | E10: =IF(ISNUMBER(D10), A10*D10, "") | F10: 150 | G10: =A10*F10 -> 1200
A11: 1 | C11: GI Faucet USA P/B;H/B | E11: =IF(ISNUMBER(D11), A11*D11, "") | F11: 270 | G11: =A11*F11 -> 270
A12: 2 | C12: GI Faucet SHARK SF2624 P/B | E12: =IF(ISNUMBER(D12), A12*D12, "") | F12: 215 | G12: =A12*F12 -> 430
A13: 1 | C13: GI Faucet GV P/B | E13: =IF(ISNUMBER(D13), A13*D13, "") | F13: 200 | G13: =A13*F13 -> 200
A14: 1 | C14: 2-Way Faucet FLEXCO FC9007 | E14: =IF(ISNUMBER(D14), A14*D14, "") | F14: 215 | G14: =A14*F14 -> 215
A15: 1 | C15: Lockable Bibbcock Faucet SF2631 | E15: =IF(ISNUMBER(D15), A15*D15, "") | F15: 175 | G15: =A15*F15 -> 175
A16: 4 | C16: GI Faucet LAMCO 12334 PLAIN BIB | E16: =IF(ISNUMBER(D16), A16*D16, "") | F16: 260 | G16: =A16*F16 -> 1040
A17: 15 | C17: PVC Faucet T-Handle PH | E17: =IF(ISNUMBER(D17), A17*D17, "") | F17: 55 | G17: =A17*F17 -> 825
A18: 2 | C18: Swing Valve SHARK #1/2 | E18: =IF(ISNUMBER(D18), A18*D18, "") | F18: 225 | G18: =A18*F18 -> 450
A19: 2 | C19: Ball Valve w/ Lock #1/2 SW | E19: =IF(ISNUMBER(D19), A19*D19, "") | F19: 320 | G19: =A19*F19 -> 640
... A28: 1 | C28: FLAP DISK 4" #100 | E28: =IF(ISNUMBER(D28), A28*D28, "") | F28: 40 | G28: =A28*F28 -> 40
C29: Total | E29: =SUM(E8:E28) -> 0 | G29: =SUM(G8:G28) -> 14450

Sheet Quote 23
A1: Fanvill Hardware Cabalwan | G1: PRICE QUOTE
A2: CABAL-AWAN TACLOBAN
A4: Name / Address | D4: Rep | E4: Project | F4: Date | G4: Quote #
A5: FANVILL CABALAWAN. | D5: AIZA | F5: 10/5/2026 | G5: 23
A7: Qty | B7: U/M | C7: Item | D7: Unit Capital | E7: Total Capital | F7: Unit Price | G7: Total Selling Price
A8: 13 | C8: PPR Male Elbow #1 | E8: =IF(ISNUMBER(D8), A8*D8, "") | F8: 315 | G8: =A8*F8 -> 4095
A9: 10 | C9: PPR Male Elbow 3/4 | E9: =IF(ISNUMBER(D9), A9*D9, "") | F9: 150 | G9: =A9*F9 -> 1500
A10: 10 | C10: PPR Male Tee 3/4 | E10: =IF(ISNUMBER(D10), A10*D10, "") | F10: 175 | G10: =A10*F10 -> 1750
A11: 52 | C11: PPR Coupling #1 | E11: =IF(ISNUMBER(D11), A11*D11, "") | F11: 25 | G11: =A11*F11 -> 1300
A12: 10 | C12: PPR Female Elbow #1 | E12: =IF(ISNUMBER(D12), A12*D12, "") | F12: 315 | G12: =A12*F12 -> 3150
A13: 1 | C13: PPR Female Tee 1/2 | E13: =IF(ISNUMBER(D13), A13*D13, "") | F13: 120 | G13: =A13*F13 -> 120
A14: 6 | C14: PPR Female Elbow 3/4 | E14: =IF(ISNUMBER(D14), A14*D14, "") | F14: 145 | G14: =A14*F14 -> 870
A15: 23 | C15: PPR Coupling 3/4 | E15: =IF(ISNUMBER(D15), A15*D15, "") | F15: 20 | G15: =A15*F15 -> 460
A16: 9 | C16: PPR Elbow 3/4x45 | E16: =IF(ISNUMBER(D16), A16*D16, "") | F16: 20 | G16: =A16*F16 -> 180
A17: 20 | C17: PPR Tee 3/4 | E17: =IF(ISNUMBER(D17), A17*D17, "") | F17: 30 | G17: =A17*F17 -> 600
A18: 4 | C18: PPR Coupling Red. 1x3/4 | E18: =IF(ISNUMBER(D18), A18*D18, "") | F18: 20 | G18: =A18*F18 -> 80
A19: 33 | C19: PPR Coupling Red. 3/4x1/2 | E19: =IF(ISNUMBER(D19), A19*D19, "") | F19: 15 | G19: =A19*F19 -> 495
... A21: 2 | C21: PPR Female Adaptor #1 | E21: =IF(ISNUMBER(D21), A21*D21, "") | F21: 270 | G21: =A21*F21 -> 540
C22: Total | E22: =SUM(E8:E21) -> 0 | G22: =SUM(G8:G21) -> 20640

Sheet Quote 24
A1: Fanvill Hardware Cabalwan | G1: PRICE QUOTE
A2: CABAL-AWAN TACLOBAN
A4: Name / Address | D4: Rep | E4: Project | F4: Date | G4: Quote #
A5: FANVILL CABALAWAN. | D5: AIZA | F5: 10/2/2026 | G5: 24
A7: Qty | B7: U/M | C7: Item | D7: Unit Capital | E7: Total Capital | F7: Unit Price | G7: Total Selling Price
A8: 55 | C8: PVC Blue Plug #1 | E8: =IF(ISNUMBER(D8), A8*D8, "") | F8: 20 | G8: =A8*F8 -> 1100
A9: 55 | C9: PVC Blue Plug #3/4 | E9: =IF(ISNUMBER(D9), A9*D9, "") | F9: 15 | G9: =A9*F9 -> 825
A10: 46 | C10: PVC Blue Plug #1/2 | E10: =IF(ISNUMBER(D10), A10*D10, "") | F10: 15 | G10: =A10*F10 -> 690
A11: 32 | C11: PVC Blue End Cap #3/4 | E11: =IF(ISNUMBER(D11), A11*D11, "") | F11: 15 | G11: =A11*F11 -> 480
A12: 79 | C12: PVC Blue End Cap #1/2 | E12: =IF(ISNUMBER(D12), A12*D12, "") | F12: 15 | G12: =A12*F12 -> 1185
A13: 23 | C13: PVC Blue Tee #1 P | E13: =IF(ISNUMBER(D13), A13*D13, "") | F13: 20 | G13: =A13*F13 -> 460
A14: 11 | C14: PVC Blue Tee #3/4 P | E14: =IF(ISNUMBER(D14), A14*D14, "") | F14: 20 | G14: =A14*F14 -> 220
A15: 12 | C15: PVC Blue Tee #1/2 P | E15: =IF(ISNUMBER(D15), A15*D15, "") | F15: 15 | G15: =A15*F15 -> 180
A16: 64 | C16: PVC Blue Tee #3/4 P | E16: =IF(ISNUMBER(D16), A16*D16, "") | F16: 20 | G16: =A16*F16 -> 1280
C17: Total | E17: =SUM(E8:E16) -> 0 | G17: =SUM(G8:G16) -> 6420

Sheet Quote 25
A1: Fanvill Hardware Cabalwan | G1: PRICE QUOTE
A2: CABAL-AWAN TACLOBAN
A4: Name / Address | D4: Rep | E4: Project | F4: Date | G4: Quote #
A5: FANVILL CABALAWAN. | D5: AIZA | F5: 10/7/2026 | G5: 25
A7: Qty | B7: U/M | C7: Item | D7: Unit Capital | E7: Total Capital | F7: Unit Price | G7: Total Selling Price
A8: 98 | C8: Utility Box (Asstd.) | E8: =IF(ISNUMBER(D8), A8*D8, "") | F8: 35 | G8: =A8*F8 -> 3430
C9: Total | E9: =SUM(E8:E8) -> 0 | G9: =SUM(G8:G8) -> 3430

Sheet Quote 26
A1: Fanvill Hardware Cabalwan | G1: PRICE QUOTE
A2: CABAL-AWAN TACLOBAN
A4: Name / Address | D4: Rep | E4: Project | F4: Date | G4: Quote #
A5: FANVILL CABALAWAN. | D5: AIZA | F5: 10/5/2026 | G5: 26
A7: Qty | B7: U/M | C7: Item | D7: Unit Capital | E7: Total Capital | F7: Unit Price | G7: Total Selling Price
A8: 10 | C8: PPR Female Tee Red. 3/4x1/2 | E8: =IF(ISNUMBER(D8), A8*D8, "") | F8: 120 | G8: =A8*F8 -> 1200
A9: 13 | C9: PPR Tee Red. 3/4x1/2 | E9: =IF(ISNUMBER(D9), A9*D9, "") | F9: 30 | G9: =A9*F9 -> 390
A10: 8 | C10: PPR Female Elbow Red. 3/4x1/2 | E10: =IF(ISNUMBER(D10), A10*D10, "") | F10: 110 | G10: =A10*F10 -> 880
A11: 8 | C11: PPR Male Elbow Red. 3/4X1/2 | E11: =IF(ISNUMBER(D11), A11*D11, "") | F11: 140 | G11: =A11*F11 -> 1120
A12: 2 | C12: PPR Tee Red. 1x1/2 | E12: =IF(ISNUMBER(D12), A12*D12, "") | F12: 40 | G12: =A12*F12 -> 80
A13: 10 | C13: PPR FTA Red. 3/4x1/2 | E13: =IF(ISNUMBER(D13), A13*D13, "") | F13: 120 | G13: =A13*F13 -> 1200
A14: 6 | C14: PPR MTA Red. 3/4x1/2 | E14: =IF(ISNUMBER(D14), A14*D14, "") | F14: 140 | G14: =A14*F14 -> 840
A15: 14 | C15: PPR Tee Red. 1x3/4 | E15: =IF(ISNUMBER(D15), A15*D15, "") | F15: 45 | G15: =A15*F15 -> 630
A16: 28 | C16: PPR Elbow 1/2x45 | E16: =IF(ISNUMBER(D16), A16*D16, "") | F16: 15 | G16: =A16*F16 -> 420
A17: 3 | C17: PPR Tee 3/4 | E17: =IF(ISNUMBER(D17), A17*D17, "") | F17: 30 | G17: =A17*F17 -> 90
A18: 27 | C18: PPR Plug #1 | E18: =IF(ISNUMBER(D18), A18*D18, "") | F18: 25 | G18: =A18*F18 -> 675
A19: 15 | C19: PPR Plug 3/4 | E19: =IF(ISNUMBER(D19), A19*D19, "") | F19: 20 | G19: =A19*F19 -> 300
... A35: 2 | C35: PPR Male Adaptor #1 | E35: =IF(ISNUMBER(D35), A35*D35, "") | F35: 325 | G35: =A35*F35 -> 650
C36: Total | E36: =SUM(E8:E35) -> 0 | G36: =SUM(G8:G35) -> 26275

Sheet Quote 27
A1: Fanvill Hardware Cabalwan | G1: PRICE QUOTE
A2: CABAL-AWAN TACLOBAN
A4: Name / Address | D4: Rep | E4: Project | F4: Date | G4: Quote #
A5: FANVILL CABALAWAN. | D5: AIZA | F5: 10/12/2026 | G5: 27
A7: Qty | B7: U/M | C7: Item | D7: Unit Capital | E7: Total Capital | F7: Unit Price | G7: Total Selling Price
A8: 2 | C8: SALE Gooseneck SUNRISE 1206 | E8: =IF(ISNUMBER(D8), A8*D8, "") | F8: 355 | G8: =A8*F8 -> 710
A9: 5 | C9: SALE Gooseneck S-1332 Sunrise | E9: =IF(ISNUMBER(D9), A9*D9, "") | F9: 230 | G9: =A9*F9 -> 1150
A10: 11 | C10: Sink Faucet SHARKSF2300C 1/2X2 | E10: =IF(ISNUMBER(D10), A10*D10, "") | F10: 215 | G10: =A10*F10 -> 2365
A11: 20 | C11: SALE SinkFaucet SharkSF2310ABS | E11: =IF(ISNUMBER(D11), A11*D11, "") | F11: 180 | G11: =A11*F11 -> 3600
A12: 2 | C12: SALE Shower Valve SHARK SF2540 | E12: =IF(ISNUMBER(D12), A12*D12, "") | F12: 365 | G12: =A12*F12 -> 730
A13: 1 | C13: SALE Shower Head (OHAYO) | E13: =IF(ISNUMBER(D13), A13*D13, "") | F13: 80 | G13: =A13*F13 -> 80
A14: 15 | C14: SALE Check Valve SHARK 1/2 | E14: =IF(ISNUMBER(D14), A14*D14, "") | F14: 165 | G14: =A14*F14 -> 2475
A15: 3 | C15: SALE Check Valve SHARK 3/4 | E15: =IF(ISNUMBER(D15), A15*D15, "") | F15: 270 | G15: =A15*F15 -> 810
A16: 1 | C16: SALE Check Valve SHARK #1 | E16: =IF(ISNUMBER(D16), A16*D16, "") | F16: 295 | G16: =A16*F16 -> 295
A17: 9 | C17: SALE Trowel Cement # 7 | E17: =IF(ISNUMBER(D17), A17*D17, "") | F17: 40 | G17: =A17*F17 -> 360
C18: Total | E18: =SUM(E8:E17) -> 0 | G18: =SUM(G8:G17) -> 12575

Sheet Quote 28
A1: Fanvill Hardware Cabalwan | G1: PRICE QUOTE
A2: CABAL-AWAN TACLOBAN
A4: Name / Address | D4: Rep | E4: Project | F4: Date | G4: Quote #
A5: FANVILL CABALAWAN. | D5: AIZA | F5: 10/12/2026 | G5: 28
A7: Qty | B7: U/M | C7: Item | D7: Unit Capital | E7: Total Capital | F7: Unit Price | G7: Total Selling Price
A8: 6 | C8: SALE Tel. Shower ROSCO #810HB | E8: =IF(ISNUMBER(D8), A8*D8, "") | F8: 295 | G8: =A8*F8 -> 1770
A9: 1 | C9: Telephone Shower FLEXCO | E9: =IF(ISNUMBER(D9), A9*D9, "") | F9: 500 | G9: =A9*F9 -> 500
A10: 5 | C10: SALE Tel. Shower ROSCO #809PW | E10: =IF(ISNUMBER(D10), A10*D10, "") | F10: 270 | G10: =A10*F10 -> 1350
A11: 3 | C11: SALE PVC GooseneckFaucetLAMCO | E11: =IF(ISNUMBER(D11), A11*D11, "") | F11: 150 | G11: =A11*F11 -> 450
A12: 7 | C12: SALE Shower Head SHARK SF2527 | E12: =IF(ISNUMBER(D12), A12*D12, "") | F12: 195 | G12: =A12*F12 -> 1365
C13: Total | E13: =SUM(E8:E12) -> 0 | G13: =SUM(G8:G12) -> 5435

Sheet Quote 29
A1: Fanvill Hardware Cabalwan | G1: PRICE QUOTE
A2: CABAL-AWAN TACLOBAN
A4: Name / Address | D4: Rep | E4: Project | F4: Date | G4: Quote #
A5: FANVILL CABALAWAN. | D5: AIZA | F5: 10/12/2026 | G5: 29
A7: Qty | B7: U/M | C7: Item | D7: Unit Capital | E7: Total Capital | F7: Unit Price | G7: Total Selling Price
A8: 18 | C8: SALE Circuit Breaker 40A (Royu) | E8: =IF(ISNUMBER(D8), A8*D8, "") | F8: 195 | G8: =A8*F8 -> 3510
A9: 3 | C9: SALE SafetyBreakerw/ outlet 15A | E9: =IF(ISNUMBER(D9), A9*D9, "") | F9: 412.5 | G9: =A9*F9 -> 1237.5
A10: 24 | C10: SALE PVCReceptacle#3-1/2(F/Fly) | E10: =IF(ISNUMBER(D10), A10*D10, "") | F10: 21 | G10: =A10*F10 -> 504
A11: 9 | C11: SALE PULL CHAIN SOCKET B1T1 | E11: =IF(ISNUMBER(D11), A11*D11, "") | F11: 60 | G11: =A11*F11 -> 540
A12: 16 | C12: SALE Rubber Socket B1T1 | E12: =IF(ISNUMBER(D12), A12*D12, "") | F12: 30 | G12: =A12*F12 -> 480
C13: Total | E13: =SUM(E8:E12) -> 0 | G13: =SUM(G8:G12) -> 6271.5

Sheet Quote 30
A1: Fanvill Hardware Cabalwan | G1: PRICE QUOTE
A2: CABAL-AWAN TACLOBAN
A4: Name / Address | D4: Rep | E4: Project | F4: Date | G4: Quote #
A5: FANVILL CABALAWAN. | D5: AIZA | F5: 10/12/2026 | G5: 30
A7: Qty | B7: U/M | C7: Item | D7: Unit Capital | E7: Total Capital | F7: Unit Price | G7: Total Selling Price
A8: 3 | C8: GI Union 1/2 HD | E8: =IF(ISNUMBER(D8), A8*D8, "") | F8: 105 | G8: =A8*F8 -> 315
A9: 24 | C9: GI Union 3/4 HD | E9: =IF(ISNUMBER(D9), A9*D9, "") | F9: 65 | G9: =A9*F9 -> 1560
A10: 10 | C10: GI Union 1 HD | E10: =IF(ISNUMBER(D10), A10*D10, "") | F10: 85 | G10: =A10*F10 -> 850
A11: 4 | C11: GI Coupling 1/2 LD | E11: =IF(ISNUMBER(D11), A11*D11, "") | F11: 25 | G11: =A11*F11 -> 100
A12: 6 | C12: Gi Coupling 3/4 HD | E12: =IF(ISNUMBER(D12), A12*D12, "") | F12: 40 | G12: =A12*F12 -> 240
A13: 32 | C13: Gi Coupling 3/4 LD | E13: =IF(ISNUMBER(D13), A13*D13, "") | F13: 30 | G13: =A13*F13 -> 960
A14: 4 | C14: GI Coupling 1 HD | E14: =IF(ISNUMBER(D14), A14*D14, "") | F14: 60 | G14: =A14*F14 -> 240
A15: 12 | C15: GI Tee # 1/2 LD | E15: =IF(ISNUMBER(D15), A15*D15, "") | F15: 45 | G15: =A15*F15 -> 540
A16: 6 | C16: GI Tee 1/2 HD | E16: =IF(ISNUMBER(D16), A16*D16, "") | F16: 60 | G16: =A16*F16 -> 360
A17: 16 | C17: GI Tee 3/4 HD | E17: =IF(ISNUMBER(D17), A17*D17, "") | F17: 75 | G17: =A17*F17 -> 1200
A18: 1 | C18: GI Elbow 3/4 HD | E18: =IF(ISNUMBER(D18), A18*D18, "") | F18: 70 | G18: =A18*F18 -> 70
A19: 19 | C19: GI Elbow 3/4 LD | E19: =IF(ISNUMBER(D19), A19*D19, "") | F19: 25 | G19: =A19*F19 -> 475
... A38: 47 | C38: GI Cap 1 | E38: =IF(ISNUMBER(D38), A38*D38, "") | F38: 35 | G38: =A38*F38 -> 1645
C39: Total | E39: =SUM(E8:E38) -> 0 | G39: =SUM(G8:G38) -> 18845

Sheet Quote 31
A1: Fanvill Hardware Cabalwan | G1: PRICE QUOTE
A2: CABAL-AWAN TACLOBAN
A4: Name / Address | D4: Rep | E4: Project | F4: Date | G4: Quote #
A5: FANVILL CABALAWAN. | D5: AIZA | F5: 10/15/2026 | G5: 31
A7: Qty | B7: U/M | C7: Item | D7: Unit Capital | E7: Total Capital | F7: Unit Price | G7: Total Selling Price
A8: 7 | C8: Ball Valve 1/2 LAMCO | E8: =IF(ISNUMBER(D8), A8*D8, "") | F8: 200 | G8: =A8*F8 -> 1400
A9: 16 | C9: SALE Ball Valve 3/4 LAMCO | E9: =IF(ISNUMBER(D9), A9*D9, "") | F9: 210 | G9: =A9*F9 -> 3360
A10: 7 | C10: Ball Valve # 1 Lamco | E10: =IF(ISNUMBER(D10), A10*D10, "") | F10: 450 | G10: =A10*F10 -> 3150
A11: 12 | C11: SALE GateValve 1/2 SHARK SF2915 | E11: =IF(ISNUMBER(D11), A11*D11, "") | F11: 215 | G11: =A11*F11 -> 2580
A12: 10 | C12: Gate Valve 3/4 SHARK | E12: =IF(ISNUMBER(D12), A12*D12, "") | F12: 355 | G12: =A12*F12 -> 3550
A13: 6 | C13: SALE Gate Valve #1 SHARK SF2917 | E13: =IF(ISNUMBER(D13), A13*D13, "") | F13: 365 | G13: =A13*F13 -> 2190
A14: 12 | C14: SALE Foot Valve #1/2 SW | E14: =IF(ISNUMBER(D14), A14*D14, "") | F14: 170 | G14: =A14*F14 -> 2040
A15: 1 | C15: SALE Foot Valve #3/4 SW | E15: =IF(ISNUMBER(D15), A15*D15, "") | F15: 250 | G15: =A15*F15 -> 250
A16: 1 | C16: SALE Foot Valve 1/2 Clayton | E16: =IF(ISNUMBER(D16), A16*D16, "") | F16: 95 | G16: =A16*F16 -> 95
A17: 1 | C17: SALE Check Valve SHARK 1/2 | E17: =IF(ISNUMBER(D17), A17*D17, "") | F17: 165 | G17: =A17*F17 -> 165
A18: 1 | C18: SALE Check Valve SHARK 3/4 | E18: =IF(ISNUMBER(D18), A18*D18, "") | F18: 270 | G18: =A18*F18 -> 270
A19: 2 | C19: SALE Foot Valve SHARK #1 | E19: =IF(ISNUMBER(D19), A19*D19, "") | F19: 240 | G19: =A19*F19 -> 480
... A23: 20 | C23: Shower Head LD/CHROME | E23: =IF(ISNUMBER(D23), A23*D23, "") | F23: 110 | G23: =A23*F23 -> 2200
C24: Total | E24: =SUM(E8:E23) -> 0 | G24: =SUM(G8:G23) -> 27295

Sheet Quote 32
A1: Fanvill Hardware Cabalwan | G1: PRICE QUOTE
A2: CABAL-AWAN TACLOBAN
A4: Name / Address | D4: Rep | E4: Project | F4: Date | G4: Quote #
A5: FANVILL CABALAWAN. | D5: AIZA | F5: 10/15/2026 | G5: 32
A7: Qty | B7: U/M | C7: Item | D7: Unit Capital | E7: Total Capital | F7: Unit Price | G7: Total Selling Price
A8: 1200 | C8: Blind Rivets 3/16 X 1 | E8: =IF(ISNUMBER(D8), A8*D8, "") | F8: 1 | G8: =A8*F8 -> 1200
A9: 2750 | C9: Blind Rivets 3/16 x 3/4 | E9: =IF(ISNUMBER(D9), A9*D9, "") | F9: 1 | G9: =A9*F9 -> 2750
A10: 580 | C10: Blind Rivets 3/16 x 5/8 | E10: =IF(ISNUMBER(D10), A10*D10, "") | F10: 1 | G10: =A10*F10 -> 580
A11: 820 | C11: Blind Rivets 3/16 x 3/8 | E11: =IF(ISNUMBER(D11), A11*D11, "") | F11: 1 | G11: =A11*F11 -> 820
A12: 1600 | C12: Blind Rivets 5/32 x 1/4 | E12: =IF(ISNUMBER(D12), A12*D12, "") | F12: 1 | G12: =A12*F12 -> 1600
A13: 1650 | B13: pc | C13: Blind Rivets 5/32 x 1/2 | E13: =IF(ISNUMBER(D13), A13*D13, "") | F13: 1 | G13: =A13*F13 -> 1650
A14: 1500 | C14: Blind Rivets 1/8 X 1 | E14: =IF(ISNUMBER(D14), A14*D14, "") | F14: 1 | G14: =A14*F14 -> 1500
A15: 2720 | C15: Blind Rivets 1/8 x 1/4 | E15: =IF(ISNUMBER(D15), A15*D15, "") | F15: 1 | G15: =A15*F15 -> 2720
A16: 1900 | C16: Blind Rivets 1/8 x 7/16 | E16: =IF(ISNUMBER(D16), A16*D16, "") | F16: 1 | G16: =A16*F16 -> 1900
A17: 800 | C17: Blind Rivets 1/8 x 3/8 | E17: =IF(ISNUMBER(D17), A17*D17, "") | F17: 1 | G17: =A17*F17 -> 800
A18: 1200 | C18: Blind Rivets 3/16 x 1/2 | E18: =IF(ISNUMBER(D18), A18*D18, "") | F18: 1 | G18: =A18*F18 -> 1200
A19: 320 | C19: Blind Rivets 1/8 x 1/2 | E19: =IF(ISNUMBER(D19), A19*D19, "") | F19: 1 | G19: =A19*F19 -> 320
A20: 100 | C20: Blind Rivets 5/32 x 3/8 | E20: =IF(ISNUMBER(D20), A20*D20, "") | F20: 1 | G20: =A20*F20 -> 100
A21: 100 | C21: Blind Rivets 5/32 x 7/16 | E21: =IF(ISNUMBER(D21), A21*D21, "") | F21: 1 | G21: =A21*F21 -> 100
C22: Total | E22: =SUM(E8:E21) -> 0 | G22: =SUM(G8:G21) -> 17240

Sheet Quote 33
A1: Fanvill Hardware Cabalwan | G1: PRICE QUOTE
A2: CABAL-AWAN TACLOBAN
A4: Name / Address | D4: Rep | E4: Project | F4: Date | G4: Quote #
A5: FANVILL CABALAWAN. | D5: AIZA | F5: 10/16/2026 | G5: 33
A7: Qty | B7: U/M | C7: Item | D7: Unit Capital | E7: Total Capital | F7: Unit Price | G7: Total Selling Price
A8: 1 | C8: PVC Blue Elbow #1/2 P | E8: =IF(ISNUMBER(D8), A8*D8, "") | F8: 15 | G8: =A8*F8 -> 15
A9: 3 | C9: PVC Blue Elbow #3/4 P | E9: =IF(ISNUMBER(D9), A9*D9, "") | F9: 15 | G9: =A9*F9 -> 45
A10: 1 | C10: PVC Blue Elbow #1 P | E10: =IF(ISNUMBER(D10), A10*D10, "") | F10: 20 | G10: =A10*F10 -> 20
A11: 3 | C11: PVC Blue Tee #1 T | E11: =IF(ISNUMBER(D11), A11*D11, "") | F11: 20 | G11: =A11*F11 -> 60
A12: 10 | C12: PVC Blue Tee #1 P | E12: =IF(ISNUMBER(D12), A12*D12, "") | F12: 20 | G12: =A12*F12 -> 200
A13: 25 | C13: SALE PNS Long Elbow 3/4 | E13: =IF(ISNUMBER(D13), A13*D13, "") | F13: 17 | G13: =A13*F13 -> 425
C14: Total | E14: =SUM(E8:E13) -> 0 | G14: =SUM(G8:G13) -> 765

Sheet Quote 34
A1: Fanvill Hardware Cabalwan | G1: PRICE QUOTE
A2: CABAL-AWAN TACLOBAN
A4: Name / Address | D4: Rep | E4: Project | F4: Date | G4: Quote #
A5: FANVILL CABALAWAN. | D5: AIZA | F5: 10/16/2026 | G5: 34
A7: Qty | B7: U/M | C7: Item | D7: Unit Capital | E7: Total Capital | F7: Unit Price | G7: Total Selling Price
A8: 20 | C8: SALE Square Box (PVC) | E8: =IF(ISNUMBER(D8), A8*D8, "") | F8: 64 | G8: =A8*F8 -> 1280
A9: 188 | C9: SALE PNS Short Elbow 3/4 | E9: =IF(ISNUMBER(D9), A9*D9, "") | F9: 14 | G9: =A9*F9 -> 2632
A10: 78 | C10: SALE PNS Long Elbow 3/4 | E10: =IF(ISNUMBER(D10), A10*D10, "") | F10: 17 | G10: =A10*F10 -> 1326
C11: Total | E11: =SUM(E8:E10) -> 0 | G11: =SUM(G8:G10) -> 5238

Sheet Quote 35
A1: Fanvill Hardware Cabalwan | G1: PRICE QUOTE
A2: CABAL-AWAN TACLOBAN
A4: Name / Address | D4: Rep | E4: Project | F4: Date | G4: Quote #
A5: FANVILL CABALAWAN. | D5: AIZA | F5: 10/16/2026 | G5: 35
A7: Qty | B7: U/M | C7: Item | D7: Unit Capital | E7: Total Capital | F7: Unit Price | G7: Total Selling Price
A8: 54 | C8: SALE PNS Long Elbow 1 | E8: =IF(ISNUMBER(D8), A8*D8, "") | F8: 27 | G8: =A8*F8 -> 1458
A9: 20 | C9: PVC Blue Male Adaptor #1-1/4 | E9: =IF(ISNUMBER(D9), A9*D9, "") | F9: 25 | G9: =A9*F9 -> 500
A10: 13 | C10: PVC Blue Female Adaptor #1-1/2 | E10: =IF(ISNUMBER(D10), A10*D10, "") | F10: 30 | G10: =A10*F10 -> 390
A11: 4 | C11: PVC Blue Female Adaptor #2 | E11: =IF(ISNUMBER(D11), A11*D11, "") | F11: 40 | G11: =A11*F11 -> 160
C12: Total | E12: =SUM(E8:E11) -> 0 | G12: =SUM(G8:G11) -> 2508

Sheet Quote 36
A1: Fanvill Hardware Cabalwan | G1: PRICE QUOTE
A2: CABAL-AWAN TACLOBAN
A4: Name / Address | D4: Rep | E4: Project | F4: Date | G4: Quote #
A5: FANVILL CABALAWAN. | D5: AIZA | F5: 10/17/2026 | G5: 36
A7: Qty | B7: U/M | C7: Item | D7: Unit Capital | E7: Total Capital | F7: Unit Price | G7: Total Selling Price
A8: 32 | C8: SALE Circuit Breaker 40A (Royu) | E8: =IF(ISNUMBER(D8), A8*D8, "") | F8: 195 | G8: =A8*F8 -> 6240
A9: 20 | C9: Staple Wire #1/2 (box) | E9: =IF(ISNUMBER(D9), A9*D9, "") | F9: 45 | G9: =A9*F9 -> 900
A10: 4 | C10: Electrode Holder 500A JacksonLD | E10: =IF(ISNUMBER(D10), A10*D10, "") | F10: 270 | G10: =A10*F10 -> 1080
A11: 25 | C11: SALE Hose Coupling #3/4 Metal | E11: =IF(ISNUMBER(D11), A11*D11, "") | F11: 42 | G11: =A11*F11 -> 1050
A12: 26 | C12: SALE Rubber Socket B1T1 | E12: =IF(ISNUMBER(D12), A12*D12, "") | F12: 30 | G12: =A12*F12 -> 780
A13: 12 | C13: Flapper Ball Orange SW | E13: =IF(ISNUMBER(D13), A13*D13, "") | F13: 95 | G13: =A13*F13 -> 1140
A14: 12 | C14: SALE Hose Coupling #1/2 Metal | E14: =IF(ISNUMBER(D14), A14*D14, "") | F14: 34 | G14: =A14*F14 -> 408
A15: 12 | C15: Circuit Breaker 40A (R) Bolt-on | E15: =IF(ISNUMBER(D15), A15*D15, "") | F15: 300 | G15: =A15*F15 -> 3600
A16: 10 | C16: SALE PVCReceptacle#3-1/2(F/Fly) | E16: =IF(ISNUMBER(D16), A16*D16, "") | F16: 21 | G16: =A16*F16 -> 210
A17: 10 | C17: IRWIN MASONRY 1/8 HD | E17: =IF(ISNUMBER(D17), A17*D17, "") | F17: 85 | G17: =A17*F17 -> 850
A18: 20 | C18: IRWIN MASONRY 5/32 HD | E18: =IF(ISNUMBER(D18), A18*D18, "") | F18: 90 | G18: =A18*F18 -> 1800
A19: 10 | C19: IRWIN MASONRY 3/8 HD | E19: =IF(ISNUMBER(D19), A19*D19, "") | F19: 200 | G19: =A19*F19 -> 2000
A20: 6 | C20: Circuit Breaker 15A (Royu) | E20: =IF(ISNUMBER(D20), A20*D20, "") | F20: 245 | G20: =A20*F20 -> 1470
C21: Total | E21: =SUM(E8:E20) -> 0 | G21: =SUM(G8:G20) -> 21528

Sheet Quote 37
A1: Fanvill Hardware Cabalwan | G1: PRICE QUOTE
A2: CABAL-AWAN TACLOBAN
A4: Name / Address | D4: Rep | E4: Project | F4: Date | G4: Quote #
A5: FANVILL CABALAWAN. | D5: AIZA | F5: 10/17/2026 | G5: 37
A7: Qty | B7: U/M | C7: Item | D7: Unit Capital | E7: Total Capital | F7: Unit Price | G7: Total Selling Price
A8: 8 | C8: SALE BallValve #3/4 SHARK | E8: =IF(ISNUMBER(D8), A8*D8, "") | F8: 230 | G8: =A8*F8 -> 1840
A9: 7 | C9: Foot Valve #1-1/4 SW | E9: =IF(ISNUMBER(D9), A9*D9, "") | F9: 635 | G9: =A9*F9 -> 4445
A10: 6 | C10: Swing Valve SHARK #1 | E10: =IF(ISNUMBER(D10), A10*D10, "") | F10: 495 | G10: =A10*F10 -> 2970
A11: 4 | C11: GI Faucet SHARK SF2624 P/B | E11: =IF(ISNUMBER(D11), A11*D11, "") | F11: 215 | G11: =A11*F11 -> 860
A12: 2 | C12: Sink Faucet S/S 304 PH | E12: =IF(ISNUMBER(D12), A12*D12, "") | F12: 790 | G12: =A12*F12 -> 1580
A13: 2 | C13: LAMCO Flush Type Push Valve | E13: =IF(ISNUMBER(D13), A13*D13, "") | F13: 1345 | G13: =A13*F13 -> 2690
A14: 2 | C14: Lavatory Faucet Shark SF2408 | E14: =IF(ISNUMBER(D14), A14*D14, "") | F14: 800 | G14: =A14*F14 -> 1600
A15: 3 | C15: Pig Drinker Assorted | E15: =IF(ISNUMBER(D15), A15*D15, "") | F15: 60 | G15: =A15*F15 -> 180
A16: 19 | C16: Ball Valve #3/4 (KITZ) | E16: =IF(ISNUMBER(D16), A16*D16, "") | F16: 285 | G16: =A16*F16 -> 5415
A17: 19 | C17: Ball Valve #1 (KITZ) | E17: =IF(ISNUMBER(D17), A17*D17, "") | F17: 500 | G17: =A17*F17 -> 9500
A18: 11 | C18: Swing Valve WB #1 | E18: =IF(ISNUMBER(D18), A18*D18, "") | F18: 680 | G18: =A18*F18 -> 7480
A19: 11 | C19: Swing Valve WB #1/2 | E19: =IF(ISNUMBER(D19), A19*D19, "") | F19: 445 | G19: =A19*F19 -> 4895
... A21: 2 | C21: Gate Valve #1 (KITZ) | E21: =IF(ISNUMBER(D21), A21*D21, "") | F21: 470 | G21: =A21*F21 -> 940
C22: Total | E22: =SUM(E8:E21) -> 0 | G22: =SUM(G8:G21) -> 44795

Sheet Quote 38
A1: Fanvill Hardware Cabalwan | G1: PRICE QUOTE
A2: CABAL-AWAN TACLOBAN
A4: Name / Address | D4: Rep | E4: Project | F4: Date | G4: Quote #
A5: FANVILL CABALAWAN. | D5: AIZA | F5: 10/17/2026 | G5: 38
